# Generated by Django 3.2.13 on 2022-12-04 10:34

import django.contrib.auth.validators
import django.core.validators
from django.db import migrations, models


class Migration(migrations.Migration):

    dependencies = [
        ('accounts', '0001_initial'),
    ]

    operations = [
        migrations.CreateModel(
            name='AuthPhone',
            fields=[
                ('id', models.BigAutoField(auto_created=True, primary_key=True, serialize=False, verbose_name='ID')),
                ('created_at', models.DateTimeField(auto_now_add=True)),
                ('updated_at', models.DateTimeField(auto_now=True)),
                ('phone', models.IntegerField()),
                ('auth_number', models.IntegerField()),
            ],
            options={
                'abstract': False,
            },
        ),
        migrations.RenameField(
            model_name='user',
            old_name='blocking',
            new_name='block',
        ),
        migrations.AddField(
            model_name='user',
            name='fullname',
            field=models.CharField(blank=True, max_length=40, unique=True),
        ),
        migrations.AlterField(
            model_name='user',
            name='nickname',
            field=models.CharField(max_length=25, unique=True),
        ),
        migrations.AlterField(
            model_name='user',
            name='phone_num',
            field=models.CharField(blank=True, max_length=11, validators=[django.core.validators.RegexValidator(regex='^01([0|1|6|7|8|9]?)-?([0-9]{3,4})-?([0-9]{4})$')]),
        ),
        migrations.AlterField(
            model_name='user',
            name='username',
            field=models.CharField(error_messages={'unique': '이미 사용중인 아이디입니다.'}, max_length=25, unique=True, validators=[django.contrib.auth.validators.UnicodeUsernameValidator()]),
        ),
    ]
